Workbook
Name Cash_minimum: #REF!

Sheet Summary
A1: Summary Sheet | E1: Date | F1: =TODAY() -> 45861
D2: Job Selling Price | E2: =F52 -> 90915.735
A3: Builder | B3: Bird Dog Group | E3: Model
A4: Lot | E4: Elevation
A5: Subdivision
A6: Customer | B6: Ebert
A7: Address | B7: 2440 Beretania Circle
A8: City/St/Zip | B8: Charlotte, NC
F9: Rates/Hr
C10: Qty of Systems | D10: 4 | E10: Rough Install | F10: 26
C11: Total Ton | D11: =4+2+4+2 -> 12 | E11: Trim Install | F11: 28
E12: Technician | F12: 32
A13: Direct Cost | H13: Equipment "A"
A14: Labor | B14: Rough In | D14: ='Rough Labor'!F47 -> 5845 | F14: =D14 -> 5845 | H14: System 1 | I14: Model # | J14: Cost | K14: Main 1st Fl
B15: Finish/Trim | D15: ='Trim Labor'!F46 -> 1218 | F15: =D15 -> 1218 | H15: AHU/Furnace | I15: S9X2C100U5PSBB | J15: 1231 | K15: 4 Ton
B16: Gas Pipe | D16: ='Gas PIpe'!F38 -> 3515 | F16: =D16 -> 3515 | H16: Elec Htr/Evap Coil | I16: 5TXCC007AS3HCA | J16: 495 | K16: Gas | P16: 400
B17: Start Up | D17: 24 | E17: Job Incentive | F17: =D17*F12 -> 768 | H17: Heat Pump/AC | I17: 5TTR7048A1000A | J17: 2089
B18: Hourly | C18: 32 | D18: 24 | F18: =D18*F12 -> 768 | H18: ERV | I18: EERVR200A1P00B | J18: 904
B19: Delivery | D19: 375 | F19: =D19 -> 375 | H19: Thermostat
B20: Roof Cap | D20: 0 | F20: =D20 -> 0 | H20: Filter | I20: EFD210DLFR000A | J20: 815
B21: Job Incentive | D21: 0.05 | F21: =(F14+F15+F16+F17)*D21 -> 567.3 | H21: System 2 | I21: Model # | J21: Cost | K21: Master
B22: Warranty | D22: 0.05 | F22: =(SUM(F14:F21))*D22 -> 652.815 | H22: AHU/Furnace | I22: S9X2B060U4PSBB | J22: 1012 | K22: 2 Ton
E23: Total Labor Cost | F23: =SUM(F14:F22) -> 13709.115 | H23: Elec Htr/Evap Coil | I23: 5TXCB006AS3HCA | J23: 481 | K23: Gas
A24: Material | B24: Equipment | C24: "A" | D24: =J43 -> 15691 | F24: =D24 -> 15691 | H24: Heat Pump/AC | I24: 5TTR7024A1000A | J24: 1641
B25: Materials | C25: "B" | D25: =Materials!F999 -> 22497.01 | F25: =D25 -> 22497.01 | H25: ERV | I25: EERVR100A1P00B | J25: 727
B26: Supplies | C26: "C" | D26: 0.85% of B | F26: =0.085*F25 -> 1912.2459 | H26: Thermostat
B27: Inflation | D27: 2% A & 8% of B+C | F27: =F24*0.02+(F25+F26)*0.08 -> 2266.5605 | H27: Filter | I27: EFD175DLFR000A | J27: 762
B28: Warranty Materials | D28: 3.0% of A | F28: =0.02*F24 -> 313.82 | H28: System 3 | I28: Model # | J28: Cost | K28: 2nd Floor
E29: Total Material Cost | F29: =SUM(F24:F28) -> 42680.636 | H29: AHU/Furnace | I29: S9X2C100U5PSBB | J29: 1231 | K29: 4 Ton
A30: RIP | B30: Permit Cost | D30: 0 | F30: =D30 -> 0 | H30: Elec Htr/Evap Coil | I30: 5TXCC007AS3HCA | J30: 495
B31: Rentals | D31: 150 | F31: =D31 -> 150 | H31: Heat Pump/AC | I31: 5TTR7048A1000A | J31: 2089
B32: Backcharges | D32: 100 | F32: =D32 -> 100 | H32: ERV | I32: EERVR200A1P00B | J32: 904
B33: Freight | D33: 0.005 | F33: =D33*F29 -> 213.40318 | H33: Thermostat
E34: Total RIP Cost | F34: =SUM(F30:F33) -> 463.40318 | H34: Filter | I34: EFD210DLFR000A | J34: 815
E35: Total Direct Cost | F35: =F23+F29+F34 -> 56853.154 | H35: System 3 | I35: Model # | J35: Cost | K35: ADU Bldg
A36: Overhead | H36: AHU/Furnace | I36: S9X2B060U4PSBB | J36: 1012 | K36: 2 Ton
B37: Labor Overhead | D37: 0.1 | F37: =D37*F35 -> 5685.3154 | G37: Direct | H37: Elec Htr/Evap Coil | I37: 5TXCB006AS3HCA | J37: 481
B38: Direct Overhead | D38: 0.06 | F38: =D38*F35 -> 3411.1893 | G38: Direct | H38: Heat Pump/AC | I38: 5TTR7024A1000A | J38: 1641
B39: Admin | D39: 0.015 | F39: =D39*F35 -> 852.79732 | G39: Direct | H39: ERV | I39: EERVR100A1P00B | J39: 727
B40: Insurance | D40: 0.035 | F40: =D40*F35 -> 1989.8604 | G40: Direct | H40: Thermostat
...

Sheet Rough Labor
A1: Rough In Labor
A3: Builder | B3: =Summary!B3 -> Bird Dog Group | E3: Model | F3: =Summary!F3 -> 0
A4: Lot | B4: =Summary!B4 -> 0 | E4: Elevation | F4: =Summary!F4 -> 0
A5: Subdivision | B5: =Summary!B5 -> 0
A6: Customer | B6: =Summary!B6 -> Ebert
A7: Address | B7: =Summary!B7 -> 2440 Beretania Circle
A8: City/St/Zip | B8: =Summary!B8 -> Charlotte, NC
A10: Qty | B10: $/Ea | C10: Item | F10: Exten
A11: =Summary!D11 -> 12 | B11: 50 | C11: Tonnage (Outdoor Unit Only) | F11: =A11*B11 -> 600
A12: 2 | B12: 150 | C12: Set Air Handler - Attic | F12: =A12*B12 -> 300
B13: 150 | C13: Set Air Handler - Inside Mechanical Room | F13: =A13*B13 -> 0
A14: 2 | B14: 150 | C14: Set Air Handler - Crawl | F14: =A14*B14 -> 300
A15: 62 | B15: 20 | C15: Supply Drop (Flex, Collar, Elbow, Mastic, Cover) | F15: =A15*B15 -> 1240
A16: 16 | B16: 25 | C16: Return Drop (Flex, Collar, Elbow, Mastic, Cover) | F16: =A16*B16 -> 400
A17: 16 | B17: 15 | C17: Return Box Framing | F17: =A17*B17 -> 240
B18: 25 | C18: Return Jumper Duct | F18: =A18*B18 -> 0
A19: 4 | B19: 10 | C19: Wye | F19: =A19*B19 -> 40
A20: 9 | B20: 35 | C20: Supply Distribution Box - Large | F20: =A20*B20 -> 315
A21: 8 | B21: 15 | C21: Zone Damper (Includes Thermostat Wire) | F21: =A21*B21 -> 120
A22: 3 | B22: 35 | C22: Barometric Bypass | F22: =A22*B22 -> 105
B23: 30 | C23: Supply Plenum Horizontal Duct (4' Only) | F23: =A23*B23 -> 0
B24: 30 | C24: Supply Plenum Horizontal Duct (Each Additional 4' Only) | F24: =A24*B24 -> 0
A25: 12 | B25: 15 | C25: Exhaust Fan (RI Box, Duct, Cap) | F25: =A25*B25 -> 180
A26: 2 | B26: 55 | C26: Dryer Vent - Ducted | F26: =A26*B26 -> 110
B27: 10 | C27: Dryer Vent - Wall Cap Only | F27: =A27*B27 -> 0
A28: 2 | B28: 10 | C28: Laundry Room Transfer Grill | F28: =A28*B28 -> 20
A29: 4 | B29: 30 | C29: Copper Lineset (50' Max) | F29: =A29*B29 -> 120
A30: 2 | B30: 35 | C30: Copper Lineset (Ea Additional 25' Adder) | F30: =A30*B30 -> 70
A31: 4 | B31: 25 | C31: Pressure Test on Copper | F31: =A31*B31 -> 100
A32: 9 | B32: 20 | C32: Thermostat Wire - AHU to Wall Mount Location | F32: =A32*B32 -> 180
B33: 15 | C33: Kitchen Range Vent - 6" Through Wall | F33: =A33*B33 -> 0
B34: 55 | C34: Kitchen Range Vent - Interior 6" Vented TO Wall | F34: =A34*B34 -> 0
B35: 65 | C35: Kitchen Range Vent - Interior 7"-8" Vented TO Wall | F35: =A35*B35 -> 0
A36: 1 | B36: 110 | C36: Kitchen Range Vent - Interior 10" Vented TO Wall | F36: =A36*B36 -> 110
A37: 1 | B37: 40 | C37: Make Up Air - Kitchen Range Vent | F37: =A37*B37 -> 40
A38: 2 | B38: 65 | C38: Flue Exhaust Pipe - Water Heater Only | F38: =A38*B38 -> 130
A39: 4 | B39: 75 | C39: Flue Exhaust Pipe - Gas Furnace Only | F39: =A39*B39 -> 300
B40: 65 | C40: Combustion Air Duct | F40: =A40*B40 -> 0
A41: 4 | B41: 75 | C41: ERV | F41: =A41*B41 -> 300
A42: 4 | B42: 100 | C42: Drive Time beyond 1 hour | F42: =A42*B42 -> 400
...

Sheet Trim Labor
A1: Finish / Trim Labor
A3: Builder | B3: =Summary!B3 -> Bird Dog Group | E3: Model | F3: =Summary!F3 -> 0
A4: Lot | B4: =Summary!B4 -> 0 | E4: Elevation | F4: =Summary!F4 -> 0
A5: Subdivision | B5: =Summary!B5 -> 0
A6: Customer | B6: =Summary!B6 -> Ebert
A7: Address | B7: =Summary!B7 -> 2440 Beretania Circle
A8: City/St/Zip | B8: =Summary!B8 -> Charlotte, NC
A10: Qty | B10: $/Ea | C10: Item | F10: Exten
A11: ='Rough Labor'!A11 -> 12 | B11: 5 | C11: Tonnage (Outdoor Unit Only) | F11: =A11*B11 -> 60
A12: ='Rough Labor'!A12+'Rough Labor'!A13+'Rough Labor'!A14 -> 4 | B12: 20 | C12: Set Outdoor Unit (Includes Low Voltage Wiring) | F12: =A12*B12 -> 80
A13: ='Rough Labor'!A12+'Rough Labor'!A13+'Rough Labor'!A14 -> 4 | B13: 7.5 | C13: Wire Air Handler (Low Voltage Wiring Only) | F13: =A13*B13 -> 30
A15: ='Rough Labor'!A15 -> 62 | B15: 2 | C15: Supply Register | F15: =A15*B15 -> 124
A16: ='Rough Labor'!A16 -> 16 | B16: 3.5 | C16: Return Grill | F16: =A16*B16 -> 56
A17: ='Rough Labor'!A26+'Rough Labor'!A27 -> 2 | B17: 3.5 | C17: Laundry Room Transfer Grill | F17: =A17*B17 -> 7
A18: ='Rough Labor'!A21 -> 8 | B18: 5 | C18: Zone Damper Wire Connections | F18: =A18*B18 -> 40
A19: ='Rough Labor'!A22 -> 3 | B19: 5 | C19: Barometric Bypass Set Up | F19: =A19*B19 -> 15
A20: ='Rough Labor'!A25 -> 12 | B20: 5 | C20: Exhaust Fan Motor and Cover Install | F20: =A20*B20 -> 60
A21: ='Rough Labor'!A25 -> 12 | B21: 2 | C21: Exhaust Fan Wall/Soffit Cap Verification | F21: =A21*B21 -> 24
A22: ='Rough Labor'!A26+'Rough Labor'!A27 -> 2 | B22: 2 | C22: Dryer Vent Wall Cap Verifiication | F22: =A22*B22 -> 4
F23: =A23*B23 -> 0
A24: ='Rough Labor'!A12+'Rough Labor'!A13+'Rough Labor'!A14 -> 4 | B24: 7.5 | C24: Copper Connections Outside (per system) | F24: =A24*B24 -> 30
A25: ='Rough Labor'!A12+'Rough Labor'!A13+'Rough Labor'!A14 -> 4 | B25: 7.5 | C25: Copper Connections Inside (per system) | F25: =A25*B25 -> 30
A26: ='Rough Labor'!A12+'Rough Labor'!A13+'Rough Labor'!A14 -> 4 | B26: 15 | C26: Vacuum Lineset | F26: =A26*B26 -> 60
A27: ='Rough Labor'!A32 -> 9 | B27: 6 | C27: Thermostat Wiring and Mounting (per Thermostat | F27: =A27*B27 -> 54
F28: =A28*B28 -> 0
A29: ='Rough Labor'!A33+'Rough Labor'!A34+'Rough Labor'!A35+'Rough Labor'!A36 -> 1 | B29: 24 | C29: Kitchen Range Vent Connection | F29: =A29*B29 -> 24
B30: 30 | C30: Kitchen Range Hood Mount | F30: =A30*B30 -> 0
A31: 1 | B31: 250 | C31: Kitchen Range Hood Mount - Canopy | F31: =A31*B31 -> 250
A32: 1 | B32: 15 | C32: Make Up Air Wiring | F32: =A32*B32 -> 15
A33: 1 | B33: 55 | C33: Third Floor Adder | F33: =A33*B33 -> 55
F34: =A34*B34 -> 0
B35: 25 | C35: Reinstall Condensate Drain | F35: =A35*B35 -> 0
B36: 20 | C36: Extend Lineset for Outdoor Unit, Braze | F36: =A36*B36 -> 0
B37: 25 | C37: Braze Lineset in Attic Space | F37: =A37*B37 -> 0
B38: 20 | C38: Uncover Return, Supply, or Laundry Grill | F38: =A38*B38 -> 0
B39: 50 | C39: Find Leak or Kinked Lineset - Braze and Pressure Test | F39: =A39*B39 -> 0
B40: 40 | C40: Level Outdoor Unit beyond normal | F40: =A40*B40 -> 0
A41: 4 | B41: 50 | C41: Drive Time beyond 1 hour | F41: =A41*B41 -> 200
B42: 50 | C42: Relocate Exhaust Fan - Reconnect Ductworki | F42: =A42*B42 -> 0
B43: 25 | C43: Uncover Thermostat Wire - Each | F43: =A43*B43 -> 0
...

Sheet Gas PIpe
A1: Gas Pipe
A3: Builder | B3: =Summary!B3 -> Bird Dog Group | E3: Model | F3: =Summary!F3 -> 0
A4: Lot | B4: =Summary!B4 -> 0 | E4: Elevation | F4: =Summary!F4 -> 0
A5: Subdivision | B5: =Summary!B5 -> 0
A6: Customer | B6: =Summary!B6 -> Ebert
A7: Address | B7: =Summary!B7 -> 2440 Beretania Circle
A8: City/St/Zip | B8: =Summary!B8 -> Charlotte, NC
A10: Qty | B10: $/Ea | C10: Item | F10: Exten
A11: =Summary!D11 -> 12 | B11: 5 | C11: Tonnage | F11: =A11*B11 -> 60
A12: 3 | B12: 65 | C12: Meter / House Set Up | F12: =A12*B12 -> 195
A13: 20 | B13: 40 | C13: Per Gas Opening (Furnace, WH, FP, Range, Etc) | F13: =A13*B13 -> 800
A14: 4 | B14: 60 | C14: Per Gas Opening - Tankless WH | F14: =A14*B14 -> 240
A15: 3 | B15: 30 | C15: Upsize Gas Main to Manifold - ½" up to ¾" CSST | F15: =A15*B15 -> 90
A16: 5 | B16: 30 | C16: Upsize Home Room Gas Line - ½" up to ¾" CSST | F16: =A16*B16 -> 150
B18: 50 | C18: Log Lighter - Includes Key Valve | F18: =A18*B18 -> 0
A19: 5 | B19: 15 | C19: Manifold | F19: =A19*B19 -> 75
A20: 2 | B20: 30 | C20: Appliance Box | F20: =A20*B20 -> 60
A21: 5 | B21: 30 | C21: Key Valve | F21: =A21*B21 -> 150
F22: =A22*B22 -> 0
A23: 7 | B23: 50 | C23: Gas Lantern Set Up (Per Lantern) | F23: =A23*B23 -> 350
F24: =A24*B24 -> 0
A25: 5 | B25: 25 | C25: Home Run Gas Line Length Adder (25' - 50') | F25: =A25*B25 -> 125
A26: 8 | B26: 50 | C26: Home Run Gas Line Length Adder (51' -100') | F26: =A26*B26 -> 400
A27: 7 | B27: 100 | C27: Home Run Gas Line Length Adder (100'+) | F27: =A27*B27 -> 700
F28: =A28*B28 -> 0
A29: 4 | B29: 30 | C29: Air Test - Pressure | F29: =A29*B29 -> 120
F30: =A30*B30 -> 0
B31: 50 | C31: Drive Time beyond 1 hour | F31: =A31*B31 -> 0
B32: 25 | C32: Uncover Appliance Box | F32: =A32*B32 -> 0
B33: 75 | C33: Re Pressure Air Test (Includes Trip Charge) | F33: =A33*B33 -> 0
B34: 55 | C34: Third Floor Adder | F34: =A34*B34 -> 0
B35: 50 | C35: Find Leak - Gas Line | F35: =A35*B35 -> 0
E38: Total | F38: =SUM(F11:F37) -> 3515
E40: 0 | F40: Dryer
E41: 2 | F41: Fireplace - Indoor
E42: 1 | F42: Fireplace - Outdoor
E43: 2 | F43: Future Outdoor Opening
E44: 4 | F44: Gas Furnace
E45: 1 | F45: Outdoor Grill
E46: 2 | F46: Outdoor Range
...

Sheet Materials
A1: MATERIALS | I1: 10000 | J1: Carrier Equipment | L1: 20000 | M1: Metal Fittings | O1: 29000 | P1: Cu and Refrig
I2: 12000 | J2: Run Tru Equipment | L2: 23000 | M2: Flex and Pipe | O2: 30000 | P2: Finish
A3: Builder | B3: =Summary!B3 -> Bird Dog Group | E3: Model | F3: =Summary!F3 -> 0 | I3: 13000 | J3: Trane Equipment | L3: 24000 | M3: Non Metal Fittings | O3: 32000 | P3: Quickflash
A4: Lot | B4: =Summary!B4 -> 0 | E4: Elevation | F4: =Summary!F4 -> 0 | I4: 15000 | J4: Lennox Equipment | L4: 25000 | M4: Exhaust Fans | O4: 35000 | P4: Fire Dampers
A5: Subdivision | B5: =Summary!B5 -> 0 | I5: 17000 | J5: Mini Split | L5: 26000 | M5: Caps | O5: 39000 | P5: Supplies-Inventoried
A6: Customer | B6: =Summary!B6 -> Ebert | I6: 17600 | J6: Drain Pans | L6: 26500 | M6: Furnace Fittings | O6: 40000 | P6: Supplies-Non-inventoried
A7: Address | B7: =Summary!B7 -> 2440 Beretania Circle | I7: 18000 | J7: Plenums and Boxes | L7: 27000 | M7: Controls & Zoning | O7: 50000 | P7: Gas
A8: City/St/Zip | B8: =Summary!B8 -> Charlotte, NC | I8: 18500 | J8: Fab Items | L8: 28000 | M8: BVENT | O8: 60000 | P8: Service
O9: 70000 | P9: Tools
A10: Part No | B10: Description | C10: Quantity | D10: Net Price | E10: UM | F10: Total
A11: 10100 | B11: FJ4DNXA18L00 1.5 TON AIR HANDLER | D11: 441 | E11: each | F11: =C11*D11 -> 0
A12: 10110 | B12: FJ4DNXB24L00 2 TON AIR HANDLER | D12: 464 | E12: each | F12: =C12*D12 -> 0
A13: 10120 | B13: FJ4DNXB30L00 2.5 TON AIR HANDLER | D13: 488 | E13: each | F13: =C13*D13 -> 0
A14: 10130 | B14: FJ4DNXB36L00 3 TON AIR HANDLER | D14: 491 | E14: each | F14: =C14*D14 -> 0
A15: 10140 | B15: FJ4DNXC42L00 3.5 AIR HANDLER | D15: 632 | E15: each | F15: =C15*D15 -> 0
A16: 10150 | B16: FJ4DNXC48L00 4 TON AIR HANDLER | D16: 635 | E16: each | F16: =C16*D16 -> 0
A17: 10160 | B17: FJ4DNXD60L00 5 TON AIR HANDLER | D17: 768 | E17: each | F17: =C17*D17 -> 0
A18: 10200 | B18: 58SB0A070E17--12 80 GAS FURNACE | D18: 409 | E18: each | F18: =C18*D18 -> 0
A19: 10210 | B19: 58SB0A090E21--16 80 GAS FURNACE | D19: 437 | E19: each | F19: =C19*D19 -> 0
A20: 10220 | B20: 58SB0A090E21--20 80 GAS FURNACE | D20: 461 | E20: each | F20: =C20*D20 -> 0
A21: 10230 | B21: 58SB0B045M14--12 80 GAS FURNACE | D21: 421 | E21: each | F21: =C21*D21 -> 0
A22: 10240 | B22: 58SB0B070M14--12 80 GAS FURNACE | D22: 421 | E22: each | F22: =C22*D22 -> 0
... A213: 17120 | B213: E LITE EQUIPMENT PAD 18X38X3 | D213: 40.05 | E213: each | F213: =C213*D213 -> 0
A214: 17200 | B214: CONDENSATE PUMP PRO CP 225 | C214: 2 | D214: 45.44 | E214: each | F214: =C214*D214 -> 90.88
A215: 17210 | B215: 3/8 x 1/2 Barb x MIP - 701-012D | D215: 3.85 | E215: each | F215: =C215*D215 -> 0
A216: 17220 | B216: 3/8 x 3/4 Barb x MIP | C216: 2 | D216: 4.2 | E216: each | F216: =C216*D216 -> 8.4
A217: 17230 | B217: 1/2 x 3/4 Barb x MIP - 701-002D | D217: 3.25 | E217: each | F217: =C217*D217 -> 0
A218: 17500 | B218: 32X32X3 PLASTIC EQUIP PAD | D218: 47.93 | E218: each | F218: =C218*D218 -> 0
A219: 17510 | B219: 36X36X3 PLASTIC EQUIP PAD | C219: 4 | D219: 32.95 | E219: each | F219: =C219*D219 -> 131.8
A220: 17520 | B220: 36X40X3 PLASTIC EQUIP PAD | E220: each | F220: =C220*D220 -> 0
A221: 17600 | B221: 24X34 24GA DRN PAN NO HOLE | D221: 35.75 | E221: each | F221: =C221*D221 -> 0
A222: 17610 | B222: 30X34 24GA DRN PAN NO HOLE | D222: 36.38 | E222: each | F222: =C222*D222 -> 0
A223: 17620 | B223: 30X36 24GA DRN PAN | E223: each | F223: =C223*D223 -> 0
A224: 17630 | B224: 30X60 24GA DRN PAN | D224: 48.62 | E224: each | F224: =C224*D224 -> 0
A225: 17640 | B225: 32X70 24GA DRN PAN | E225: each | F225: =C225*D225 -> 0
A226: 17650 | B226: 34X75 24GA DRN PAN | D226: 61.95 | E226: each | F226: =C226*D226 -> 0
A227: 17660 | B227: 36X80 24GA DRN PAN | C227: 2 | D227: 65.54 | E227: each | F227: =C227*D227 -> 131.08
A228: 17670 | B228: 12X10X3-1/2 GAS BOX - NO HOLE | C228: 3 | D228: 9 | E228: each | F228: =C228*D228 -> 27
A229: 18000 | B229: 11X17X24 DB PLENUM W CAP R8 | D229: 44.68 | E229: each | F229: =C229*D229 -> 0
A230: 18010 | B230: 11X17X24 DB SLEEVE - NO CAP R8 | D230: 36.76 | E230: each | F230: =C230*D230 -> 0
...

Sheet Calc
A2: Owner's Bath 209 3088 1567 144 95 | C2: 144 | D2: =C2*C$19 -> 118.58824
A3: Owner's Suite 303 4551 4152 212 251 | C3: 251 | D3: =C3*C$19 -> 206.70588
A4: Family Room 431 3168 1807 148 109 | C4: 148 | D4: =C4*C$19 -> 121.88235
A5: Owner's WIC 212 3515 2359 164 143 | C5: 164 | D5: =C5*C$19 -> 135.05882
A6: Foyer 122 1468 1258 68 76 | C6: 76 | D6: =C6*C$19 -> 62.588235 | F6: =D13+D14+D15+D16+D17+D11+D12 -> 534.47059
A7: Study 206 2786 2160 130 131 | C7: 131 | D7: =C7*C$19 -> 107.88235 | F7: =D18-F6 -> 865.52941
A8: Study Bath 91 1319 729 61 44 | C8: 61 | D8: =C8*C$19 -> 50.235294
A9: Kitchen 268 330 1170 15 71 | C9: 71 | D9: =C9*C$19 -> 58.470588
A10: Scullery 104 118 44 5 3 | C10: 5 | D10: =C10*C$19 -> 4.1176471
A11: Casual Dining 200 4045 3473 188 210 | C11: 210 | D11: =C11*C$19 -> 172.94118
A12: 1st Stair 160 2036 1697 95 103 | C12: 103 | D12: =C12*C$19 -> 84.823529
A13: Entry Hall 112 2847 1778 133 107 | C13: 107 | D13: =C13*C$19 -> 88.117647
A14: Laundry 109 132 485 6 29 | C14: 29 | D14: =C14*C$19 -> 23.882353
A15: 1st Hall 160 0 0 0 0 | C15: 0 | D15: =C15*C$19 -> 0
A16: Billards | C16: 145 | D16: =C16*C$19 -> 119.41176
A17: Lounge | C17: 55 | D17: =C17*C$19 -> 45.294118
C18: =SUM(C2:C17) -> 1700 | D18: =SUM(D2:D17) -> 1400
C19: =C20/C18 -> 0.82352941
C20: 1400
A22: Command Center 70 927 664 35 36 | C22: 36 | D22: =C22*C$39 -> 40.862656
A23: Hall Up 285 909 825 34 45 | C23: 45 | D23: =C23*C$39 -> 51.07832
A24: 2nd Stair 160 4948 3553 187 193 | C24: 193 | D24: =C24*C$39 -> 219.06924
A25: W/D Up 32 0 0 0 0 | C25: 0 | D25: =C25*C$39 -> 0
A26: Suite 3 Bath 98 1993 1187 75 64 | C26: 75 | D26: =C26*C$39 -> 85.130533
A27: Suite 2 Bath 75 224 129 8 7 | C27: 8 | D27: =C27*C$39 -> 9.0805902
A28: Suite 2 WIC 40 120 69 5 4 | C28: 5 | D28: =C28*C$39 -> 5.6753689
A29: Suite 2 165 1854 1429 70 78 | C29: 78 | D29: =C29*C$39 -> 88.535755
A30: Bonus Room 431 4092 3143 154 171 | C30: 171 | D30: =C30*C$39 -> 194.09762
A31: Suite 3 WIC 33 97 56 4 3 | C31: 4 | D31: =C31*C$39 -> 4.5402951
A32: Suite 3 216 2855 1879 108 102 | C32: 108 | D32: =C32*C$39 -> 122.58797
A33: Suite 4 WIC 34 101 58 4 3 | C33: 4 | D33: =C33*C$39 -> 4.5402951
... A35: Suite 4 216 3356 2016 127 110 | C35: 110 | D35: =C35*C$39 -> 124.85812
A36: Unfinished Storage | D36: =C36*C$39 -> 0
A37: Future Expansion | D37: =C37*C$39 -> 0
C38: =SUM(C22:C37) -> 881 | D38: =SUM(D22:D37) -> 1000
C39: =C40/C38 -> 1.1350738
C40: 1000

Sheet Sheet2
A1: MATERIALS | I1: 1000 | J1: Boxes | L1: 2300 | M1: Cu and Refrig
I2: 1000 | J2: Metal Fittings | L2: 2500 | M2: Finish
A3: Builder | B3: =Summary!B3 -> Bird Dog Group | E3: Model | F3: =Summary!F3 -> 0 | I3: 1400 | J3: Furnace Fittings | L3: 2800 | M3: BVENT
A4: Lot | B4: =Summary!B4 -> 0 | E4: Elevation | F4: =Summary!F4 -> 0 | I4: 1500 | J4: Flex and Pipe | L4: 3000 | M4: Caps
A5: Subdivision | B5: =Summary!B5 -> 0 | I5: 2000 | J5: Non Metal Fittings | L5: 4000 | M5: Supplies
A6: Customer | B6: =Summary!B6 -> Ebert | I6: 2100 | J6: Exhaust Fans | L6: 5000 | M6: Other
A7: Address | B7: =Summary!B7 -> 2440 Beretania Circle | I7: 2200 | J7: Controls & Zoning | L7: 6000 | M7: Service | O7: 7000 | P7: Gas
A8: City/St/Zip | B8: =Summary!B8 -> Charlotte, NC
A10: Part No | B10: Description | C10: Box Qty | D10: Quantity | E10: Net Price | F10: UM | G10: Total
A11: 10000 | B11: 11-1/4X18X24 DB PLENUM W CAP R8 | E11: 31.08 | F11: EA | G11: =D11*E11 -> 0
A12: 10005 | B12: 11-1/4X18X24 DB SLEEVE NO CAP R8 | E12: 30 | F12: EA | G12: =D12*E12 -> 0
A13: 10010 | B13: 11-1/4X18X48 DB PLENUM W CAP R8 | E13: 62.16 | F13: EA | G13: =D13*E13 -> 0
A14: 10020 | B14: 14-1/2X18X24 DB PLENUM W CAP R8 | D14: 1 | E14: 33.46 | F14: EA | G14: =D14*E14 -> 33.46
A15: 10025 | B15: 14-1/2X18X48DB SLEEVE NO CAP R8 | D15: 1 | E15: 32 | F15: EA | G15: =D15*E15 -> 32
A16: 10030 | B16: 14-1/2X18X48 DB PLENUM W CAP R8 | E16: 62.58 | F16: EA | G16: =D16*E16 -> 0
A17: 10040 | B17: 18X18X24 DB PLENUM W CAP R8 | E17: 35.27 | F17: EA | G17: =D17*E17 -> 0
A18: 10045 | B18: 18X18X24 DB SLEEVE NO CAP R8 | E18: 34 | F18: EA | G18: =D18*E18 -> 0
A19: 10050 | B19: 18X18X48 DB PLENUM W CAP R8 | E19: 70.47 | F19: EA | G19: =D19*E19 -> 0
A20: 10060 | B20: 21X21X24 DB PLENUM W CAP | E20: 42.34 | F20: EA | G20: =D20*E20 -> 0
A21: 10065 | B21: 21X2IX24 DB SLEEVE NO CAP R8 | E21: 40 | F21: EA | G21: =D21*E21 -> 0
A22: 10070 | B22: 2IX21X48 DB PLENUM W CAP R8 | E22: 74.7 | F22: EA | G22: =D22*E22 -> 0
A23: 10075 | B23: 21X21X48 DB SLEEVE -NO CAP R8 | E23: 65 | F23: EA | G23: =D23*E23 -> 0
A24: 10090 | B24: LRG DB TRIANGLE DIST | D24: 2 | E24: 43.79 | F24: EA | G24: =D24*E24 -> 87.58
A25: 10100 | B25: 12-1/2 X 12-1/2 X 12 METAL BOX (UNINSUL) | E25: 12.04 | F25: EA | G25: =D25*E25 -> 0
A26: 10110 | B26: 14-1/2 X 14-1/2 X 12 METAL BOX (UNINSUL) | E26: 14.57 | F26: EA | G26: =D26*E26 -> 0
A27: 10112 | B27: 16-1/2X16-1/2 X 12 METAL BOX (UNINSUL) | E27: 15.26 | F27: EA | G27: =D27*E27 -> 0
A28: 10117 | B28: 20-1/2 X 14-1/2 X 12 METAL BOX (UNINSUL) | E28: 17.7 | F28: EA | G28: =D28*E28 -> 0
A29: 10120 | B29: 24-1/2 X 12-1/2 X 12 METAL BOX (UNINSUL) | D29: 1 | E29: 18.95 | F29: EA | G29: =D29*E29 -> 18.95
A30: 10130 | B30: 25-1/2 X14-1/2 X 12 METAL BOX (UNINSUL) | E30: 19.56 | F30: EA | G30: =D30*E30 -> 0
A31: 10140 | B31: 12-1/2 X 12-1/2 X 12 METAL BOX R8 | E31: 19.92 | F31: EA | G31: =D31*E31 -> 0
A32: 10150 | B32: 14-1/2 X 14-1/2 x 12 METAL BOX R8 | E32: 24.62 | F32: EA | G32: =D32*E32 -> 0
A33: 10160 | B33: 16-1/2 X 16-1/2 X 12 METAL BOX R8 | E33: 29.73 | F33: EA | G33: =D33*E33 -> 0
B34: 16-1/2 X 25-1/2 X 18 RTN AIR BOX R8 | E34: 29.07 | F34: EA | G34: =D34*E34 -> 0
A35: 10170 | B35: 20-1/2 X 14-1/2 X 12 METAL BOX R8 | D35: 1 | E35: 32.9 | F35: EA | G35: =D35*E35 -> 32.9
A36: 10180 | B36: 20-1/2 X 20-1/2 X 12 METAL BOX R8 | E36: 41.22 | F36: EA | G36: =D36*E36 -> 0
A37: 10190 | B37: 24-1/2 X 12-1/2 X 12 METAL BOX R8 | E37: 35.27 | F37: EA | G37: =D37*E37 -> 0
A38: 10200 | B38: 25-1/2 X 14-1/2 X 12 R8 METAL BOX R8 | E38: 53.94 | F38: EA | G38: =D38*E38 -> 0
A39: 10210 | B39: 25-1/2 X 16-1/2 X 12 METAL BOX R8 | E39: 43.13 | F39: EA | G39: =D39*E39 -> 0
A40: 10220 | B40: 25-1/2 X 20-1/2 X 12 METAL BOX R8 | E40: 49.7 | F40: EA | G40: =D40*E40 -> 0
A41: 11000 | B41: 14-1/2X24X18 PLATFORM BOX | E41: 40.62 | F41: EA | G41: =D41*E41 -> 0
...

Sheet On Call
A1: On Call Extra
A3: Date
B5: Qty | C5: Rate | D5: Item | E5: Exten
C6: 75 | D6: On Call Period / Rotating Week/Weekend
C7: 75 | D7: Holiday On Call (Per Night)
C8: 5 | D8: Answer Messages from Service Line
C9: 20 | D9: Walk Through Service Call Over Phone (15 Min max)
A11: Hrs | B11: $/Hr | C11: Address Lot/Subdivision
B12: 20
D22: Total

Sheet Extras
C1: Options and Extras
A8: Cost/Ea | B8: UoM | C8: Item
A9: 250 | B9: Ea | C9: Add One SUPPLY Drop
A10: 375 | B10: Ea | C10: Add One RETURN Opening
A11: 75 | B11: Ea | C11: Upsize One Supply or Return Duct by One Size
A12: 75 | B12: Per | C12: Extend Supply Duct to the Outside Wall
A13: 1650 | B13: Per | C13: Install Zone System
A14: 750 | B14: Ea | C14: Upsize Equipment by One HALF Ton | F14: 19250
A15: 160 | B15: Ea | C15: Add One Fan Only 50 CFM Bath (1667H & 1688F) | F15: 800
A16: 250 | B16: Ea | C16: Add One Fan/Light Combo 50 CFM (2667H & 2688F) | F16: 375
A17: 325 | B17: Ea | C17: Add One Fan Only 80 CFM Bath Fan (N671) | F17: 375
A18: 200 | B18: Ea | C18: Install Combustion Air High Low Round Duct | F18: 1650
A19: 100 | B19: Ea | C19: Install Combustion Air Grilles (North Carolina Only) | F19: =SUM(F14:F18) -> 22450
A20: 100 | B20: Ea | C20: Install Laundry Room Combustion Air Grille
A21: 200 | B21: Ea | C21: Vent Range Hood on Exterior Wall
A22: 380 | B22: Ea | C22: Vent Range Hood on Interior Wall
A23: 650 | B23: Ea | C23: 6" Fresh Air Damper - Duct and Labor Included (Honeywell Y8150 Controller)
A24: 400 | B24: Ea | C24: Dryer Vent Booster
A25: 800 | B25: Ea | C25: Install ½" Log Lighter for a Wood Burning Fireplace
A26: 475 | B26: Ea | C26: Additional Gas Line - (Fireplace, Pation, Range, Dryer, etc) ½" Gas Pipe Opening
A27: 850 | B27: Ea | C27: Add Gas Line to One Appliance (Electric Base House)
A28: 925 | B28: Ea | C28: Add Propane Gas Line to Fireplace Only
A29: 750 | B29: Ea | C29: Add Gas to Gas Water Heater (½" Gas Pipe Opening and 4" Exhaust Vent Pipe)
A30: 885 | B30: Ea | C30: Tankless Water Heater (Upsize to ¾" Gas Line Opening)
A31: Price per House | C31: Tankless Water Heater Vent Extension
A32: 575 | B32: Ea | C32: Add Full or Half Bath to Existing Room (Supply Drop and Fan/Light Combo - 50 CFM)
A33: 250 | B33: Ea | C33: Additional Lineset Extension Up to 15 ft Only
A34: 375 | B34: Ea | C34: Additional Lineset Extension 16 ft to 35 Ft Only
A35: 575 | B35: Ea | C35: Additional Lineset Extension Up to an additional 50 Ft
A36: 1375 | B36: Ea | C36: Honeywell Humidifier (HM509H8910) w/ Compatible Thermostat (TH9421U1002)
A37: 3400 | B37: Ea | C37: Dehumidifier with Ductwork
A38: 3250 | B38: Ea | C38: Dehumidifier without Ductwork
A39: 400 | B39: Ea | C39: Aprilaire 4" Media Air Cleaner - Includes Filter
A40: 1850 | B40: Ea | C40: Sales Office - Includes Ductwork, 4 SA Drop, 1 RA and Builder Supplied Equipment
A41: 150 | B41: Ea | C41: Trip Charge
A42: 175 | B42: Ea | C42: Cabarrus County Permit Increase
A43: 175 | B43: Ea | C43: Iredell County Permit Increase
... A60: 625 | B60: Ea | C60: HVAC Code ADDER - Raleigh

Sheet Time Card
E1: WEEKLY TIMESHEET | L1: Week of:
I4: Employee Name (Print)
A8: DAY | B8: Date | C8: Start Time | D8: Lunch Start | E8: Lunch End | F8: End Time | G8: Reg Hours | H8: Piece Rate Hours | I8: Total Hours Worked | J8: Job Number | K8: LOT | L8: SUBDIVISION / ADDRESS | M8: PAY
A9: MONDAY
A13: TUESDAY
A17: WEDNESDAY
A21: THURSDAY
A25: FRIDAY
A29: SATURDAY
A31: SUNDAY
A33: WEEKLY TOTALS | G33: Reg Hrs | H33: PCR Hrs | I33: Total Hrs | J33: WEEKLY PIECE RATE PAY | M33: Total PCR Pay
A36: Employee Signature | G36: Date | L36: Internal Use Only
A38: Supervisor Signature | G38: Date

Sheet Builder Info Sheet
F1: HVAC / BUILDER INFORMATION SHEET | L1: Date
B6: Lot | J6: Builder
B7: Subdivision | J7: Contact
B8: Customer Name | J8: Email
B9: Address | J9: Address
B10: City / St | J10: City / St
B11: County | J11: Billing Contact
J12: Billing Email
A13: House Faces (Front Door) | E13: N / E / S / W
A15: Wall Type | F15: Roof Type
B16: Wood | D16: R11 | G16: Shingle | I16: R30
B17: Block | D17: R13 | G17: Metal | I17: R38
D18: R17 | G18: Tile | I18: Icynene
D19: Icynene
A20: Window Type
B21: DBL Pane | D21: Reflect
B22: Trip Pane | D22: Low E
A25: HVAC SYSTEM
B26: Qty of Systems | D26: Brand
B27: Electric / Gas
B28: Zoning
A30: Gas Pipe to | C30: Range Vent
B31: Furnace | D31: Location
B32: Water Heater | D32: Size
B33: Dryer | D33: Hang Hood
B34: Range
B35: Patio
B36: Lantern
B37: Fireplace | D37: Log Lighter
D38: Insert
A40: Duct System Type
B41: Flex | D41: Progressive
B42: Ductboard | D42: Conventional
B43: Metal

Sheet Sheet1
C1: AccountingCode1 | D1: ItemName | E1: ItemDescription | F1: PurchaseUnit | G1: UnitOfMeasure | H1: CoverageRatePurchase | I1: CoverageRateMeasured | J1: FolderLevel1 | K1: FolderLevel2 | L1: FolderLevel3 | M1: FolderLevel4 | N1: FolderLevel5 | O1: CostType1 | P1: UnitCost1 | Q1: ExportId | R1: CostType2 | S1: UnitCost2 | T1: AccountingCode2 | U1: CostType3 | V1: UnitCost3 | W1: AccountingCode3 | X1: CostType4 | Y1: UnitCost4 | Z1: AccountingCode4 | AA1: CostType5 | AB1: UnitCost5 | AC1: AccountingCode5 | AD1: ExternalId
B3: CE0501N05T 5 KW Elec Heater Fused | C3: 81250 | D3: CE0501N05T 5 KW Elec Heater Fused | E3: CE0501N05T 5 KW Elec Heater Fused | F3: each | G3: each | H3: 1 | I3: 1 | J3: Rough Equipment | O3: Material | P3: 51
B4: CE0801N08TS 8 KW Elec Heater Fused | C4: 81260 | D4: CE0801N08TS 8 KW Elec Heater Fused | E4: CE0801N08TS 8 KW Elec Heater Fused | F4: each | G4: each | H4: 1 | I4: 1 | J4: Rough Equipment | O4: Material | P4: 85
B5: CE0901N10T 10 KW Elec Heater Fused | C5: 81270 | D5: CE0901N10T 10 KW Elec Heater Fused | E5: CE0901N10T 10 KW Elec Heater Fused | F5: each | G5: each | H5: 1 | I5: 1 | J5: Rough Equipment | O5: Material | P5: 79
B6: CE3001F15T 15 KW Elec Heater Fused | C6: 81280 | D6: CE3001F15T 15 KW Elec Heater Fused | E6: CE3001F15T 15 KW Elec Heater Fused | F6: each | G6: each | H6: 1 | I6: 1 | J6: Rough Equipment | O6: Material | P6: 147
B7: 58SB0A070E17--12 80 GAS FURNACE | C7: 81430 | D7: 58SB0A070E17--12 80 GAS FURNACE | E7: 58SB0A070E17--12 80 GAS FURNACE | F7: each | G7: each | H7: 1 | I7: 1 | J7: Rough Equipment | O7: Material | P7: 409
B8: 58SB0A090E21--16 80 GAS FURNACE | C8: 81460 | D8: 58SB0A090E21--16 80 GAS FURNACE | E8: 58SB0A090E21--16 80 GAS FURNACE | F8: each | G8: each | H8: 1 | I8: 1 | J8: Rough Equipment | O8: Material | P8: 437
B9: 58SB0A090E21--20 80 GAS FURNACE | C9: 81470 | D9: 58SB0A090E21--20 80 GAS FURNACE | E9: 58SB0A090E21--20 80 GAS FURNACE | F9: each | G9: each | H9: 1 | I9: 1 | J9: Rough Equipment | O9: Material | P9: 461
B10: 59SC2D040E14--10 92 GAS FURNACE | C10: 81600 | D10: 59SC2D040E14--10 92 GAS FURNACE | E10: 59SC2D040E14--10 92 GAS FURNACE | F10: each | G10: each | H10: 1 | I10: 1 | J10: Rough Equipment | O10: Material | P10: 515
B11: 59SC2D040E17--12 92 GAS FURNACE | C11: 81610 | D11: 59SC2D040E17--12 92 GAS FURNACE | E11: 59SC2D040E17--12 92 GAS FURNACE | F11: each | G11: each | H11: 1 | I11: 1 | J11: Rough Equipment | O11: Material | P11: 515
B12: 59SC2D060E14--12 92 GAS FURNACE | C12: 81620 | D12: 59SC2D060E14--12 92 GAS FURNACE | E12: 59SC2D060E14--12 92 GAS FURNACE | F12: each | G12: each | H12: 1 | I12: 1 | J12: Rough Equipment | O12: Material | P12: 528
B13: 59SC2D060E17--14 92 GAS FURNACE | C13: 81630 | D13: 59SC2D060E17--14 92 GAS FURNACE | E13: 59SC2D060E17--14 92 GAS FURNACE | F13: each | G13: each | H13: 1 | I13: 1 | J13: Rough Equipment | O13: Material | P13: 541
B14: 59SC2D080E17--16 92 GAS FURNACE | C14: 81640 | D14: 59SC2D080E17--16 92 GAS FURNACE | E14: 59SC2D080E17--16 92 GAS FURNACE | F14: each | G14: each | H14: 1 | I14: 1 | J14: Rough Equipment | O14: Material | P14: 554
... B212: 11X17X48 DB PLENUM W CAP R8 | C212: 995 | D212: 11X17X48 DB PLENUM W CAP R8 | E212: 11X17X48 DB PLENUM W CAP R8 | F212: each | G212: each | H212: 1 | I212: 1 | J212: Rough Material | O212: Material | P212: 59.87
A213: 10000 | B213: 11-1/4X18X24 DB PLENUM W CAP R8 | C213: 10000 | D213: 11-1/4X18X24 DB PLENUM W CAP R8.. | E213: 11-1/4X18X24 DB PLENUM W CAP R8.. | F213: each | G213: each | H213: 1 | I213: 1 | J213: Rough Material | O213: Material | P213: 31.08
A214: 10005 | B214: 11-1/4X18X24 DB SLEEVE NO CAP R8 | C214: 10005 | D214: 11-1/4X18X24 DB SLEEVE - NO CAP R8 | E214: 11-1/4X18X24 DB SLEEVE - NO CAP R8 | F214: each | G214: each | H214: 1 | I214: 1 | J214: Rough Material | O214: Material | P214: 30
A215: 10010 | B215: 11-1/4X18X48 DB PLENUM W CAP R8 | C215: 10010 | D215: 11-1/4X18X48 DB PLENUM W CAP R8 | E215: 11-1/4X18X48 DB PLENUM W CAP R8 | F215: each | G215: each | H215: 1 | I215: 1 | J215: Rough Material | O215: Material | P215: 62.16
A216: 10020 | B216: 14-1/2X18X24 DB PLENUM W CAP R8 | C216: 10020 | D216: 14-1/2X18X24 DB PLENUM W CAP R8 | E216: 14-1/2X18X24 DB PLENUM W CAP R8 | F216: each | G216: each | H216: 1 | I216: 1 | J216: Rough Material | O216: Material | P216: 33.46
A217: 10025 | B217: 14-1/2X18X48DB SLEEVE NO CAP R8 | C217: 10025 | D217: 14-1/2X18X24 DB SLEEVE - NO CAP R8 | E217: 14-1/2X18X24 DB SLEEVE - NO CAP R8 | F217: each | G217: each | H217: 1 | I217: 1 | J217: Rough Material | O217: Material | P217: 32
A218: 10030 | B218: 14-1/2X18X48 DB PLENUM W CAP R8 | C218: 10030 | D218: 14-1/2X18X48 DB PLENUM W CAP R8 | E218: 14-1/2X18X48 DB PLENUM W CAP R8 | F218: each | G218: each | H218: 1 | I218: 1 | J218: Rough Material | O218: Material | P218: 62.58
A219: 10031 | B219: 14-3/4X17X24 DB PLENUM W CAP R8 | C219: 10031 | D219: 14-3/4X17X24 DB PLENUM W CAP R8 | E219: 14-3/4X17X24 DB PLENUM W CAP R8 | F219: each | G219: each | H219: 1 | I219: 1 | J219: Rough Material | O219: Material | P219: 46.71
A220: 10032 | B220: 14-3/4X17X24 DB SLEEVE - NO CAP R8 | C220: 10032 | D220: 14-3/4X17X24 DB SLEEVE - NO CAP R8 | E220: 14-3/4X17X24 DB SLEEVE - NO CAP R8 | F220: each | G220: each | H220: 1 | I220: 1 | J220: Rough Material | O220: Material | P220: 38.8
A221: 10033 | B221: 14-3/4X17X48 DB PLENUM W CAP R8 | C221: 10033 | D221: 14-3/4X17X48 DB PLENUM W CAP R8 | E221: 14-3/4X17X48 DB PLENUM W CAP R8 | F221: each | G221: each | H221: 1 | I221: 1 | J221: Rough Material | O221: Material | P221: 63.94
A222: 10034 | B222: 17X17X24 DB PLENUM W CAP R8 | C222: 10034 | D222: 17X17X24 DB PLENUM W CAP R8 | E222: 17X17X24 DB PLENUM W CAP R8 | F222: each | G222: each | H222: 1 | I222: 1 | J222: Rough Material | O222: Material | P222: 47.97
A223: 10035 | B223: 17X17X24 DB SLEEVE - NO CAP R8 | C223: 10035 | D223: 17X17X24 DB SLEEVE - NO CAP R8 | E223: 17X17X24 DB SLEEVE - NO CAP R8 | F223: each | G223: each | H223: 1 | I223: 1 | J223: Rough Material | O223: Material | P223: 40.02
A224: 10036 | B224: 17X17X48 DB PLENUM W CAP R8 | C224: 10036 | D224: 17X17X48 DB PLENUM W CAP R8 | E224: 17X17X48 DB PLENUM W CAP R8 | F224: each | G224: each | H224: 1 | I224: 1 | J224: Rough Material | O224: Material | P224: 66.39
... A243: 10120 | B243: 24-1/2 X 12-1/2 X 12 METAL BOX (UNINSUL) | C243: 10120 | D243: 24-1/2 X 12-1/2 X 12 METAL BOX (UNINSUL) | E243: 24-1/2 X 12-1/2 X 12 METAL BOX (UNINSUL) | F243: each | G243: each | H243: 1 | I243: 1 | J243: Rough Material | O243: Material | P243: 18.95
A244: 10130 | B244: 25-1/2 X14-1/2 X 12 METAL BOX (UNINSUL) | C244: 10130 | D244: 25-1/2 X 12-1/2 X 12 METAL BOX (UNINSUL)
A245: 10140 | B245: 12-1/2 X 12-1/2 X 12 METAL BOX R8 | C245: 10140 | D245: 12-1/2 X 12-1/2 X 12 RTN AIR BOX R8 | E245: 12-1/2 X 12-1/2 X 12 RTN AIR BOX R8 | F245: each | G245: each | H245: 1 | I245: 1 | J245: Rough Material | O245: Material | P245: 19.92
A246: 10150 | B246: 14-1/2 X 14-1/2 x 12 METAL BOX R8 | C246: 10150 | D246: 14-1/2 X 14-1/2 X 12 RTN AIR BOX R8 | E246: 14-1/2 X 14-1/2 X 12 RTN AIR BOX R8 | F246: each | G246: each | H246: 1 | I246: 1 | J246: Rough Material | O246: Material | P246: 24.62
A247: 10160 | B247: 16-1/2 X 16-1/2 X 12 METAL BOX R8 | C247: 10160 | D247: 16-1/2 X 16-1/2 X 12 RTN AIR BOX R8 | E247: 16-1/2 X 16-1/2 X 12 RTN AIR BOX R8 | F247: each | G247: each | H247: 1 | I247: 1 | J247: Rough Material | O247: Material | P247: 29.73
B248: 16-1/2 X 25-1/2 X 12 RTN AIR BOX R8 | C248: NS10095 | D248: 16-1/2 X 25-1/2 X 12 RTN AIR BOX R8 | E248: 16-1/2 X 25-1/2 X 123 RTN AIR BOX R8 | F248: each | G248: each | H248: 1 | I248: 1 | J248: Rough Material | O248: Material | P248: 0
A249: 10170 | B249: 20-1/2 X 14-1/2 X 12 METAL BOX R8 | C249: 10170 | D249: 20-1/2 X 14-1/2 X 12 RTN AIR BOX R8 | E249: 20-1/2 X 14-1/2 X 12 RTN AIR BOX R8 | F249: each | G249: each | H249: 1 | I249: 1 | J249: Rough Material | O249: Material | P249: 32.9
A250: 10180 | B250: 20-1/2 X 20-1/2 X 12 METAL BOX R8 | C250: 10180 | D250: 20-1/2 X 20-1/2 X 12 RTN AIR BOX R8 | E250: 20-1/2 X 20-1/2 X 12 RTN AIR BOX R8 | F250: each | G250: each | H250: 1 | I250: 1 | J250: Rough Material | O250: Material | P250: 41.22
A251: 10190 | B251: 24-1/2 X 12-1/2 X 12 METAL BOX R8 | C251: 10190 | D251: 24-1/2 X 12-1/2 X 12 RTN AIR BOX R8 | E251: 24-1/2 X 12-1/2 X 12 RTN AIR BOX R8 | F251: each | G251: each | H251: 1 | I251: 1 | J251: Rough Material | O251: Material | P251: 35.27
A252: 10200 | B252: 25-1/2 X 14-1/2 X 12 R8 METAL BOX R8 | C252: 10200 | D252: 25-1/2 X 14-1/2 X 12 RTN AIR BOX R8 | E252: 25-1/2 X 14-1/2 X 12 RTN AIR BOX R8 | F252: each | G252: each | H252: 1 | I252: 1 | J252: Rough Material | O252: Material | P252: 53.94
A253: 10210 | B253: 25-1/2 X 16-1/2 X 12 METAL BOX R8 | C253: 10210 | D253: 25-1/2 X 16-1/2 X 12 RTN AIR BOX R8 | E253: 25-1/2 X 16-1/2 X 12 RTN AIR BOX R8 | F253: each | G253: each | H253: 1 | I253: 1 | J253: Rough Material | O253: Material | P253: 43.13
A254: 10220 | B254: 25-1/2 X 20-1/2 X 12 METAL BOX R8 | C254: 10220 | D254: 25-1/2 X 20-1/2 X 12 RTN AIR BOX R8 | E254: 25-1/2 X 20-1/2 X 12 RTN AIR BOX R8 | F254: each | G254: each | H254: 1 | I254: 1 | J254: Rough Material | O254: Material | P254: 49.7
A255: 11000 | B255: 14-1/2X24X18 PLATFORM BOX | C255: 11000 | D255: 14-1/2X24X18 PLATFORM BOX | E255: 14-1/2X24X18 PLATFORM BOX | F255: each | G255: each | H255: 1 | I255: 1 | J255: Rough Material | O255: Material | P255: 40.62
A256: 11005 | B256: 14-3/4X22X18 PLATFORM BOX | C256: 11005 | D256: 14-3/4X22X18 PLATFORM BOX | E256: 14-3/4X22X18 PLATFORM BOX | F256: each | G256: each | H256: 1 | I256: 1 | J256: Rough Material | O256: Material | P256: 53.98
...

Sheet Sheet9
A1: 17200 | B1: CONDENSATE PUMP PRO CP 225 | C1: 1 | D1: 45.44 | E1: each | F1: =C1*D1 -> 45.44
A2: 17220 | B2: 3/8 x 3/4 Barb x MIP | C2: 1 | D2: 4.2 | E2: each | F2: =C2*D2 -> 4.2
A3: 17610 | B3: 30X34 24GA DRN PAN NO HOLE | C3: 1 | D3: 36.38 | E3: each | F3: =C3*D3 -> 36.38
A4: 17660 | B4: 36X80 24GA DRN PAN | C4: 1 | D4: 65.54 | E4: each | F4: =C4*D4 -> 65.54
A5: 18610 | B5: 120 26GA DRV CLEAT | C5: 2 | D5: 3.16 | E5: each | F5: =C5*D5 -> 6.32
A6: 20000 | B6: 10X4X4 STRT BOOT | C6: 7 | D6: 3.55 | E6: each | F6: =C6*D6 -> 24.85
A7: 20010 | B7: 10X4X6 STRT BOOT | C7: 10 | D7: 3.17 | E7: each | F7: =C7*D7 -> 31.7
A8: 20020 | B8: 12X4X7 STRT BOOT | C8: 6 | D8: 4.04 | E8: each | F8: =C8*D8 -> 24.24
A9: 20060 | B9: 10X4X4 90 ANGLE BOOT | C9: 1 | D9: 4.16 | E9: each | F9: =C9*D9 -> 4.16
A10: 20070 | B10: 10X4X6 90 ANGLE BOOT | C10: 3 | D10: 3.17 | E10: each | F10: =C10*D10 -> 9.51
A11: 20080 | B11: 12X4X7 90 ANGLE BOOT | C11: 2 | D11: 4.43 | E11: each | F11: =C11*D11 -> 8.86
A12: 20090 | B12: 14X4X8 90 ANGLE BOOT | C12: 1 | D12: 7.12 | E12: each | F12: =C12*D12 -> 7.12
... A92: 40095 | B92: 3/8 ID X 50 CLR VINYL TUBE - 738 | C92: 1 | D92: 13.42 | E92: each | F92: =C92*D92 -> 13.42
A93: 17210 | B93: 3/8 x 1/2 Barb x MIP - 701-012D | D93: 3.85 | E93: each | F93: =C93*D93 -> 0
A94: 17230 | B94: 1/2 x 3/4 Barb x MIP - 701-002D | D94: 3.25 | E94: each | F94: =C94*D94 -> 0
A95: 17500 | B95: 32X32X3 PLASTIC EQUIP PAD | D95: 47.93 | E95: each | F95: =C95*D95 -> 0
A96: 17520 | B96: 36X40X3 PLASTIC EQUIP PAD | E96: each | F96: =C96*D96 -> 0
A97: 17600 | B97: 24X34 24GA DRN PAN NO HOLE | D97: 35.75 | E97: each | F97: =C97*D97 -> 0
A98: 17620 | B98: 30X36 24GA DRN PAN | E98: each | F98: =C98*D98 -> 0
A99: 17630 | B99: 30X60 24GA DRN PAN | D99: 48.62 | E99: each | F99: =C99*D99 -> 0
A100: 17640 | B100: 32X70 24GA DRN PAN | E100: each | F100: =C100*D100 -> 0
A101: 17650 | B101: 34X75 24GA DRN PAN | D101: 61.95 | E101: each | F101: =C101*D101 -> 0
A102: 17670 | B102: 12X10X3-1/2 GAS BOX - NO HOLE | D102: 9 | E102: each | F102: =C102*D102 -> 0
A103: 18000 | B103: 11X17X24 DB PLENUM W CAP R8 | D103: 44.68 | E103: each | F103: =C103*D103 -> 0
A104: 18010 | B104: 11X17X24 DB SLEEVE - NO CAP R8 | D104: 36.76 | E104: each | F104: =C104*D104 -> 0
A105: 18020 | B105: 11X17X48 DB PLENUM W CAP R8 | D105: 59.87 | E105: each | F105: =C105*D105 -> 0
A106: 18030 | B106: 11-1/4X18X24 DB PLENUM W CAP R8 | D106: 31.08 | E106: each | F106: =C106*D106 -> 0
A107: 18040 | B107: 11-1/4X18X24 DB SLEEVE NO CAP R8 | D107: 30 | E107: each | F107: =C107*D107 -> 0
A108: 18050 | B108: 11-1/4X18X48 DB PLENUM W CAP R8 | D108: 62.16 | E108: each | F108: =C108*D108 -> 0
A109: 18060 | B109: 14-1/2X18X24 DB PLENUM W CAP R8 | D109: 33.46 | E109: each | F109: =C109*D109 -> 0
A110: 18070 | B110: 14-1/2X18X48DB SLEEVE NO CAP R8 | D110: 32 | E110: each | F110: =C110*D110 -> 0
A111: 18080 | B111: 14-1/2X18X48 DB PLENUM W CAP R8 | D111: 62.58 | E111: each | F111: =C111*D111 -> 0
A112: 18100 | B112: 14-3/4X17X24 DB SLEEVE - NO CAP R8 | D112: 38.8 | E112: each | F112: =C112*D112 -> 0
... A146: 18540 | B146: 4X4 WALL CAP HOOD - LINESET COVER | D146: 7 | E146: each | F146: =C146*D146 -> 0
A147: 18550 | B147: IX48X120 2" R8 DB 6 SHT | E147: each | F147: =C147*D147 -> 0
A148: 18560 | B148: 48X96 24 GA SHEET METAL | E148: each | F148: =C148*D148 -> 0
A149: 18570 | B149: 48X96 26 GA SHEET METAL | D149: 41.17 | E149: each | F149: =C149*D149 -> 0
A150: 18590 | B150: 1/2" x 1-1/2"-48" DRYWALLFRAME | D150: 2.75 | E150: each | F150: =C150*D150 -> 0
A151: 18600 | B151: 120 26GA S CLEAT | D151: 5.95 | E151: each | F151: =C151*D151 -> 0
A152: 18620 | B152: 120 28GA DRV CLEAT | D152: 3.68 | E152: each | F152: =C152*D152 -> 0
...
